Workbook
Name Ausleihen: Ausleihen!$A$1:$D$47
Name Ausleihen: Gesamt!$A$1:$D$47
Name Ausleihen: GesamtMitDuplikaten!$A$1:$D$47
Name Geraete: Geraete!$A$1:$F$37
Name Mitarbeiter: Mitarbeiter!$A$1:$D$13

Sheet Mitarbeiter
A1: Mitarbeiter-ID | B1: Name | C1: Abteilung | D1: Standort
A2: 1001 | B2: Aleksandr Weinhage | C2: IT | D2: Berlin
A3: 1002 | B3: Eleni Hauffer | C3: IT | D3: Berlin
A4: 1003 | B4: Paul Dobes-Stiffel | C4: Produktion | D4: Hamburg
A5: 1004 | B5: Klemens Löffler | C5: Vertrieb | D5: Hamburg
A6: 1005 | B6: Alexandre Davids | C6: Vertrieb | D6: Berlin
A7: 1006 | B7: Eric Patberg B.Sc. | C7: Vertrieb | D7: Hamburg
A8: 1007 | B8: Orhan Siering MBA. | C8: IT | D8: Berlin
A9: 1008 | B9: Dipl.-Ing. Klaus-Werner Holsten B.Sc. | C9: IT | D9: Hamburg
A10: 1009 | B10: Univ.Prof. Heimo Karge | C10: Marketing | D10: Hamburg
A11: 1010 | B11: Carolin Hande | C11: IT | D11: Hamburg
A12: 1011 | B12: Auguste Davids | C12: IT | D12: Hamburg
A13: 1012 | B13: Ariane Klemt-Kaul | C13: IT | D13: München

Sheet Ausleihen
A1: Gerätenummer | B1: Mitarbeiter-ID | C1: Ausgabe am | D1: Rückgabe am
A2: G0004 | B2: 1003 | C2: 45827 | D2: 45908
A3: G0004 | B3: 1001 | C3: 45880 | D3: 45881
A4: G0005 | B4: 1009 | C4: 45389
A5: G0005 | B5: 1006 | C5: 45892 | D5: 45922
A6: G0005 | B6: 1012 | C6: 45599
A7: G0005 | B7: 1010 | C7: 45899 | D7: 45925
A8: G0006 | B8: 1012 | C8: 45808 | D8: 45818
A9: G0006 | B9: 1007 | C9: 45476
A10: G0007 | B10: 1001 | C10: 45544 | D10: 45854
A11: G0007 | B11: 1001 | C11: 45880
A12: G0009 | B12: 1011 | C12: 45850 | D12: 45853
A13: G0011 | B13: 1005 | C13: 45837 | D13: 45898
A14: G0013 | B14: 1012 | C14: 45419 | D14: 45470
A15: G0013 | B15: 1009 | C15: 45319 | D15: 45714
A16: G0014 | B16: 1001 | C16: 45622 | D16: 45719
A17: G0015 | B17: 1010 | C17: 45377 | D17: 45886
A18: G0015 | B18: 1002 | C18: 45519
A19: G0016 | B19: 1010 | C19: 45866
A20: G0016 | B20: 1002 | C20: 45799 | D20: 45808
A21: G0016 | B21: 1003 | C21: 45330 | D21: 45817
A22: G0016 | B22: 1007 | C22: 45795 | D22: 45846
A23: G0016 | B23: 1010 | C23: 45808 | D23: 45932
A24: G0018 | B24: 1011 | C24: 45568 | D24: 45623
A25: G0021 | B25: 1008 | C25: 45930 | D25: 45935
A26: G0022 | B26: 1002 | C26: 45899 | D26: 45930
A27: G0022 | B27: 1002 | C27: 45493 | D27: 45663
A28: G0024 | B28: 1005 | C28: 45743 | D28: 45868
A29: G0024 | B29: 1008 | C29: 45375
A30: G0025 | B30: 1005 | C30: 45675
A31: G0027 | B31: 1004 | C31: 45403 | D31: 45839
A32: G0028 | B32: 1004 | C32: 45523
A33: G0028 | B33: 1006 | C33: 45630 | D33: 45732
A34: G0028 | B34: 1003 | C34: 45595 | D34: 45630
A35: G0029 | B35: 1002 | C35: 45921 | D35: 45934
A36: G0030 | B36: 1012 | C36: 45792 | D36: 45905
A37: G0030 | B37: 1005 | C37: 45261 | D37: 45559
A38: G0031 | B38: 1004 | C38: 45320
A39: G0031 | B39: 1004 | C39: 45336
A40: G0032 | B40: 1003 | C40: 45508 | D40: 45871
...

Sheet Geraete
A1: Gerätenummer | B1: Gerätetyp | C1: Modell | D1: Kaufdatum | E1: Netto-Kaufpreis | F1: Standort
A2: G0001 | B2: Tablet | C2: Galaxy Tab | D2: 44937 | E2: 1342.83 | F2: Berlin
A3: G0002 | B3: Tablet | C3: Surface Go | D3: 44250 | E3: 1076.18 | F3: München
A4: G0003 | B4: Tablet | C4: iPad | D4: 45543 | E4: 1931.54 | F4: München
A5: G0004 | B5: Laptop | C5: Dell XPS | D5: 45782 | E5: 1007.88 | F5: München
A6: G0005 | B6: Drucker | C6: Canon Pixma | D6: 44503 | E6: 823.23 | F6: Berlin
A7: G0006 | B7: Smartphone | C7: Samsung S21 | D7: 45292 | E7: 1257.96 | F7: München
A8: G0007 | B8: Laptop | C8: Lenovo ThinkPad | D8: 44360 | E8: 869.09 | F8: Hamburg
A9: G0008 | B9: Beamer | C9: Epson EB | D9: 45831 | E9: 1323.76 | F9: Hamburg
A10: G0009 | B10: Laptop | C10: Dell XPS | D10: 45026 | E10: 1458.02 | F10: München
A11: G0010 | B11: Laptop | C11: Dell XPS | D11: 45239 | E11: 1786.37 | F11: München
A12: G0011 | B12: Drucker | C12: Brother HL | D12: 45909 | E12: 1417.1 | F12: München
A13: G0012 | B13: Tablet | C13: Galaxy Tab | D13: 44713 | E13: 968.43 | F13: Hamburg
... A36: G0035 | B36: Beamer | C36: BenQ MW550 | D36: 45294 | E36: 644.54 | F36: Berlin

Sheet GesamtMitDuplikaten
A1: Gerätenummer | B1: Mitarbeiter-ID | C1: Ausgabe am | D1: Rückgabe am | E1: Gerätetyp | F1: Modell | G1: Kaufdatum | H1: Netto-Kaufpreis | I1: Standort | J1: Name | K1: Abteilung | L1: Standort
A2: G0004 | B2: 1003 | C2: 45827 | D2: 45908 | E2: {=_xlfn.XLOOKUP(A2,Geraete!A:A,Geraete!B:F,"not found",0,1)} -> Laptop | F2: Dell XPS | G2: 45782 | H2: 1007.88 | I2: München | J2: {=_xlfn.XLOOKUP(GesamtMitDuplikaten!B2,Mitarbeiter!A:A,Mitarbeiter!B:D,"not found",0,1)} -> Paul Dobes-Stiffel | K2: Produktion | L2: Hamburg
A3: G0004 | B3: 1001 | C3: 45880 | D3: 45881 | E3: {=_xlfn.XLOOKUP(A3,Geraete!A:A,Geraete!B:F,"not found",0,1)} -> Laptop | F3: Dell XPS | G3: 45782 | H3: 1007.88 | I3: München | J3: {=_xlfn.XLOOKUP(GesamtMitDuplikaten!B3,Mitarbeiter!A:A,Mitarbeiter!B:D,"not found",0,1)} -> Aleksandr Weinhage | K3: IT | L3: Berlin
A4: G0005 | B4: 1009 | C4: 45389 | E4: {=_xlfn.XLOOKUP(A4,Geraete!A:A,Geraete!B:F,"not found",0,1)} -> Drucker | F4: Canon Pixma | G4: 44503 | H4: 823.23 | I4: Berlin | J4: {=_xlfn.XLOOKUP(GesamtMitDuplikaten!B4,Mitarbeiter!A:A,Mitarbeiter!B:D,"not found",0,1)} -> Univ.Prof. Heimo Karge | K4: Marketing | L4: Hamburg
A5: G0005 | B5: 1006 | C5: 45892 | D5: 45922 | E5: {=_xlfn.XLOOKUP(A5,Geraete!A:A,Geraete!B:F,"not found",0,1)} -> Drucker | F5: Canon Pixma | G5: 44503 | H5: 823.23 | I5: Berlin | J5: {=_xlfn.XLOOKUP(GesamtMitDuplikaten!B5,Mitarbeiter!A:A,Mitarbeiter!B:D,"not found",0,1)} -> Eric Patberg B.Sc. | K5: Vertrieb | L5: Hamburg
A6: G0005 | B6: 1012 | C6: 45599 | E6: {=_xlfn.XLOOKUP(A6,Geraete!A:A,Geraete!B:F,"not found",0,1)} -> Drucker | F6: Canon Pixma | G6: 44503 | H6: 823.23 | I6: Berlin | J6: {=_xlfn.XLOOKUP(GesamtMitDuplikaten!B6,Mitarbeiter!A:A,Mitarbeiter!B:D,"not found",0,1)} -> Ariane Klemt-Kaul | K6: IT | L6: München
A7: G0005 | B7: 1010 | C7: 45899 | D7: 45925 | E7: {=_xlfn.XLOOKUP(A7,Geraete!A:A,Geraete!B:F,"not found",0,1)} -> Drucker | F7: Canon Pixma | G7: 44503 | H7: 823.23 | I7: Berlin | J7: {=_xlfn.XLOOKUP(GesamtMitDuplikaten!B7,Mitarbeiter!A:A,Mitarbeiter!B:D,"not found",0,1)} -> Carolin Hande | K7: IT | L7: Hamburg
A8: G0006 | B8: 1012 | C8: 45808 | D8: 45818 | E8: {=_xlfn.XLOOKUP(A8,Geraete!A:A,Geraete!B:F,"not found",0,1)} -> Smartphone | F8: Samsung S21 | G8: 45292 | H8: 1257.96 | I8: München | J8: {=_xlfn.XLOOKUP(GesamtMitDuplikaten!B8,Mitarbeiter!A:A,Mitarbeiter!B:D,"not found",0,1)} -> Ariane Klemt-Kaul | K8: IT | L8: München
A9: G0006 | B9: 1007 | C9: 45476 | E9: {=_xlfn.XLOOKUP(A9,Geraete!A:A,Geraete!B:F,"not found",0,1)} -> Smartphone | F9: Samsung S21 | G9: 45292 | H9: 1257.96 | I9: München | J9: {=_xlfn.XLOOKUP(GesamtMitDuplikaten!B9,Mitarbeiter!A:A,Mitarbeiter!B:D,"not found",0,1)} -> Orhan Siering MBA. | K9: IT | L9: Berlin
A10: G0007 | B10: 1001 | C10: 45544 | D10: 45854 | E10: {=_xlfn.XLOOKUP(A10,Geraete!A:A,Geraete!B:F,"not found",0,1)} -> Laptop | F10: Lenovo ThinkPad | G10: 44360 | H10: 869.09 | I10: Hamburg | J10: {=_xlfn.XLOOKUP(GesamtMitDuplikaten!B10,Mitarbeiter!A:A,Mitarbeiter!B:D,"not found",0,1)} -> Aleksandr Weinhage | K10: IT | L10: Berlin
A11: G0007 | B11: 1001 | C11: 45880 | E11: {=_xlfn.XLOOKUP(A11,Geraete!A:A,Geraete!B:F,"not found",0,1)} -> Laptop | F11: Lenovo ThinkPad | G11: 44360 | H11: 869.09 | I11: Hamburg | J11: {=_xlfn.XLOOKUP(GesamtMitDuplikaten!B11,Mitarbeiter!A:A,Mitarbeiter!B:D,"not found",0,1)} -> Aleksandr Weinhage | K11: IT | L11: Berlin
A12: G0009 | B12: 1011 | C12: 45850 | D12: 45853 | E12: {=_xlfn.XLOOKUP(A12,Geraete!A:A,Geraete!B:F,"not found",0,1)} -> Laptop | F12: Dell XPS | G12: 45026 | H12: 1458.02 | I12: München | J12: {=_xlfn.XLOOKUP(GesamtMitDuplikaten!B12,Mitarbeiter!A:A,Mitarbeiter!B:D,"not found",0,1)} -> Auguste Davids | K12: IT | L12: Hamburg
A13: G0011 | B13: 1005 | C13: 45837 | D13: 45898 | E13: {=_xlfn.XLOOKUP(A13,Geraete!A:A,Geraete!B:F,"not found",0,1)} -> Drucker | F13: Brother HL | G13: 45909 | H13: 1417.1 | I13: München | J13: {=_xlfn.XLOOKUP(GesamtMitDuplikaten!B13,Mitarbeiter!A:A,Mitarbeiter!B:D,"not found",0,1)} -> Alexandre Davids | K13: Vertrieb | L13: Berlin
A14: G0013 | B14: 1012 | C14: 45419 | D14: 45470 | E14: {=_xlfn.XLOOKUP(A14,Geraete!A:A,Geraete!B:F,"not found",0,1)} -> Drucker | F14: Canon Pixma | G14: 44332 | H14: 1898.65 | I14: Hamburg | J14: {=_xlfn.XLOOKUP(GesamtMitDuplikaten!B14,Mitarbeiter!A:A,Mitarbeiter!B:D,"not found",0,1)} -> Ariane Klemt-Kaul | K14: IT | L14: München
A15: G0013 | B15: 1009 | C15: 45319 | D15: 45714 | E15: {=_xlfn.XLOOKUP(A15,Geraete!A:A,Geraete!B:F,"not found",0,1)} -> Drucker | F15: Canon Pixma | G15: 44332 | H15: 1898.65 | I15: Hamburg | J15: {=_xlfn.XLOOKUP(GesamtMitDuplikaten!B15,Mitarbeiter!A:A,Mitarbeiter!B:D,"not found",0,1)} -> Univ.Prof. Heimo Karge | K15: Marketing | L15: Hamburg
A16: G0014 | B16: 1001 | C16: 45622 | D16: 45719 | E16: {=_xlfn.XLOOKUP(A16,Geraete!A:A,Geraete!B:F,"not found",0,1)} -> Laptop | F16: Lenovo ThinkPad | G16: 44258 | H16: 1415.97 | I16: Hamburg | J16: {=_xlfn.XLOOKUP(GesamtMitDuplikaten!B16,Mitarbeiter!A:A,Mitarbeiter!B:D,"not found",0,1)} -> Aleksandr Weinhage | K16: IT | L16: Berlin
A17: G0015 | B17: 1010 | C17: 45377 | D17: 45886 | E17: {=_xlfn.XLOOKUP(A17,Geraete!A:A,Geraete!B:F,"not found",0,1)} -> Smartphone | F17: iPhone 13 | G17: 44824 | H17: 661.44 | I17: München | J17: {=_xlfn.XLOOKUP(GesamtMitDuplikaten!B17,Mitarbeiter!A:A,Mitarbeiter!B:D,"not found",0,1)} -> Carolin Hande | K17: IT | L17: Hamburg
A18: G0015 | B18: 1002 | C18: 45519 | E18: {=_xlfn.XLOOKUP(A18,Geraete!A:A,Geraete!B:F,"not found",0,1)} -> Smartphone | F18: iPhone 13 | G18: 44824 | H18: 661.44 | I18: München | J18: {=_xlfn.XLOOKUP(GesamtMitDuplikaten!B18,Mitarbeiter!A:A,Mitarbeiter!B:D,"not found",0,1)} -> Eleni Hauffer | K18: IT | L18: Berlin
A19: G0016 | B19: 1010 | C19: 45866 | E19: {=_xlfn.XLOOKUP(A19,Geraete!A:A,Geraete!B:F,"not found",0,1)} -> Drucker | F19: Canon Pixma | G19: 45015 | H19: 1501.06 | I19: Berlin | J19: {=_xlfn.XLOOKUP(GesamtMitDuplikaten!B19,Mitarbeiter!A:A,Mitarbeiter!B:D,"not found",0,1)} -> Carolin Hande | K19: IT | L19: Hamburg
A20: G0016 | B20: 1002 | C20: 45799 | D20: 45808 | E20: {=_xlfn.XLOOKUP(A20,Geraete!A:A,Geraete!B:F,"not found",0,1)} -> Drucker | F20: Canon Pixma | G20: 45015 | H20: 1501.06 | I20: Berlin | J20: {=_xlfn.XLOOKUP(GesamtMitDuplikaten!B20,Mitarbeiter!A:A,Mitarbeiter!B:D,"not found",0,1)} -> Eleni Hauffer | K20: IT | L20: Berlin
A21: G0016 | B21: 1003 | C21: 45330 | D21: 45817 | E21: {=_xlfn.XLOOKUP(A21,Geraete!A:A,Geraete!B:F,"not found",0,1)} -> Drucker | F21: Canon Pixma | G21: 45015 | H21: 1501.06 | I21: Berlin | J21: {=_xlfn.XLOOKUP(GesamtMitDuplikaten!B21,Mitarbeiter!A:A,Mitarbeiter!B:D,"not found",0,1)} -> Paul Dobes-Stiffel | K21: Produktion | L21: Hamburg
A22: G0016 | B22: 1007 | C22: 45795 | D22: 45846 | E22: {=_xlfn.XLOOKUP(A22,Geraete!A:A,Geraete!B:F,"not found",0,1)} -> Drucker | F22: Canon Pixma | G22: 45015 | H22: 1501.06 | I22: Berlin | J22: {=_xlfn.XLOOKUP(GesamtMitDuplikaten!B22,Mitarbeiter!A:A,Mitarbeiter!B:D,"not found",0,1)} -> Orhan Siering MBA. | K22: IT | L22: Berlin
A23: G0016 | B23: 1010 | C23: 45808 | D23: 45932 | E23: {=_xlfn.XLOOKUP(A23,Geraete!A:A,Geraete!B:F,"not found",0,1)} -> Drucker | F23: Canon Pixma | G23: 45015 | H23: 1501.06 | I23: Berlin | J23: {=_xlfn.XLOOKUP(GesamtMitDuplikaten!B23,Mitarbeiter!A:A,Mitarbeiter!B:D,"not found",0,1)} -> Carolin Hande | K23: IT | L23: Hamburg
A24: G0018 | B24: 1011 | C24: 45568 | D24: 45623 | E24: {=_xlfn.XLOOKUP(A24,Geraete!A:A,Geraete!B:F,"not found",0,1)} -> Tablet | F24: iPad | G24: 44839 | H24: 1688.07 | I24: München | J24: {=_xlfn.XLOOKUP(GesamtMitDuplikaten!B24,Mitarbeiter!A:A,Mitarbeiter!B:D,"not found",0,1)} -> Auguste Davids | K24: IT | L24: Hamburg
A25: G0021 | B25: 1008 | C25: 45930 | D25: 45935 | E25: {=_xlfn.XLOOKUP(A25,Geraete!A:A,Geraete!B:F,"not found",0,1)} -> Monitor | F25: Samsung Curved | G25: 44979 | H25: 1134.16 | I25: München | J25: {=_xlfn.XLOOKUP(GesamtMitDuplikaten!B25,Mitarbeiter!A:A,Mitarbeiter!B:D,"not found",0,1)} -> Dipl.-Ing. Klaus-Werner Holsten B.Sc. | K25: IT | L25: Hamburg
A26: G0022 | B26: 1002 | C26: 45899 | D26: 45930 | E26: {=_xlfn.XLOOKUP(A26,Geraete!A:A,Geraete!B:F,"not found",0,1)} -> Tablet | F26: iPad | G26: 45524 | H26: 1591.98 | I26: Hamburg | J26: {=_xlfn.XLOOKUP(GesamtMitDuplikaten!B26,Mitarbeiter!A:A,Mitarbeiter!B:D,"not found",0,1)} -> Eleni Hauffer | K26: IT | L26: Berlin
A27: G0022 | B27: 1002 | C27: 45493 | D27: 45663 | E27: {=_xlfn.XLOOKUP(A27,Geraete!A:A,Geraete!B:F,"not found",0,1)} -> Tablet | F27: iPad | G27: 45524 | H27: 1591.98 | I27: Hamburg | J27: {=_xlfn.XLOOKUP(GesamtMitDuplikaten!B27,Mitarbeiter!A:A,Mitarbeiter!B:D,"not found",0,1)} -> Eleni Hauffer | K27: IT | L27: Berlin
A28: G0024 | B28: 1005 | C28: 45743 | D28: 45868 | E28: {=_xlfn.XLOOKUP(A28,Geraete!A:A,Geraete!B:F,"not found",0,1)} -> Monitor | F28: Dell UltraSharp | G28: 44621 | H28: 750.91 | I28: Berlin | J28: {=_xlfn.XLOOKUP(GesamtMitDuplikaten!B28,Mitarbeiter!A:A,Mitarbeiter!B:D,"not found",0,1)} -> Alexandre Davids | K28: Vertrieb | L28: Berlin
A29: G0024 | B29: 1008 | C29: 45375 | E29: {=_xlfn.XLOOKUP(A29,Geraete!A:A,Geraete!B:F,"not found",0,1)} -> Monitor | F29: Dell UltraSharp | G29: 44621 | H29: 750.91 | I29: Berlin | J29: {=_xlfn.XLOOKUP(GesamtMitDuplikaten!B29,Mitarbeiter!A:A,Mitarbeiter!B:D,"not found",0,1)} -> Dipl.-Ing. Klaus-Werner Holsten B.Sc. | K29: IT | L29: Hamburg
A30: G0025 | B30: 1005 | C30: 45675 | E30: {=_xlfn.XLOOKUP(A30,Geraete!A:A,Geraete!B:F,"not found",0,1)} -> Beamer | F30: Epson EB | G30: 45266 | H30: 545.46 | I30: Berlin | J30: {=_xlfn.XLOOKUP(GesamtMitDuplikaten!B30,Mitarbeiter!A:A,Mitarbeiter!B:D,"not found",0,1)} -> Alexandre Davids | K30: Vertrieb | L30: Berlin
A31: G0027 | B31: 1004 | C31: 45403 | D31: 45839 | E31: {=_xlfn.XLOOKUP(A31,Geraete!A:A,Geraete!B:F,"not found",0,1)} -> Monitor | F31: Samsung Curved | G31: 44766 | H31: 501.64 | I31: München | J31: {=_xlfn.XLOOKUP(GesamtMitDuplikaten!B31,Mitarbeiter!A:A,Mitarbeiter!B:D,"not found",0,1)} -> Klemens Löffler | K31: Vertrieb | L31: Hamburg
A32: G0028 | B32: 1004 | C32: 45523 | E32: {=_xlfn.XLOOKUP(A32,Geraete!A:A,Geraete!B:F,"not found",0,1)} -> Beamer | F32: Epson EB | G32: 44945 | H32: 1246.58 | I32: Hamburg | J32: {=_xlfn.XLOOKUP(GesamtMitDuplikaten!B32,Mitarbeiter!A:A,Mitarbeiter!B:D,"not found",0,1)} -> Klemens Löffler | K32: Vertrieb | L32: Hamburg
A33: G0028 | B33: 1006 | C33: 45630 | D33: 45732 | E33: {=_xlfn.XLOOKUP(A33,Geraete!A:A,Geraete!B:F,"not found",0,1)} -> Beamer | F33: Epson EB | G33: 44945 | H33: 1246.58 | I33: Hamburg | J33: {=_xlfn.XLOOKUP(GesamtMitDuplikaten!B33,Mitarbeiter!A:A,Mitarbeiter!B:D,"not found",0,1)} -> Eric Patberg B.Sc. | K33: Vertrieb | L33: Hamburg
A34: G0028 | B34: 1003 | C34: 45595 | D34: 45630 | E34: {=_xlfn.XLOOKUP(A34,Geraete!A:A,Geraete!B:F,"not found",0,1)} -> Beamer | F34: Epson EB | G34: 44945 | H34: 1246.58 | I34: Hamburg | J34: {=_xlfn.XLOOKUP(GesamtMitDuplikaten!B34,Mitarbeiter!A:A,Mitarbeiter!B:D,"not found",0,1)} -> Paul Dobes-Stiffel | K34: Produktion | L34: Hamburg
A35: G0029 | B35: 1002 | C35: 45921 | D35: 45934 | E35: {=_xlfn.XLOOKUP(A35,Geraete!A:A,Geraete!B:F,"not found",0,1)} -> Laptop | F35: Lenovo ThinkPad | G35: 44337 | H35: 1553.15 | I35: Hamburg | J35: {=_xlfn.XLOOKUP(GesamtMitDuplikaten!B35,Mitarbeiter!A:A,Mitarbeiter!B:D,"not found",0,1)} -> Eleni Hauffer | K35: IT | L35: Berlin
A36: G0030 | B36: 1012 | C36: 45792 | D36: 45905 | E36: {=_xlfn.XLOOKUP(A36,Geraete!A:A,Geraete!B:F,"not found",0,1)} -> Beamer | F36: Epson EB | G36: 44647 | H36: 1629.76 | I36: München | J36: {=_xlfn.XLOOKUP(GesamtMitDuplikaten!B36,Mitarbeiter!A:A,Mitarbeiter!B:D,"not found",0,1)} -> Ariane Klemt-Kaul | K36: IT | L36: München
A37: G0030 | B37: 1005 | C37: 45261 | D37: 45559 | E37: {=_xlfn.XLOOKUP(A37,Geraete!A:A,Geraete!B:F,"not found",0,1)} -> Beamer | F37: Epson EB | G37: 44647 | H37: 1629.76 | I37: München | J37: {=_xlfn.XLOOKUP(GesamtMitDuplikaten!B37,Mitarbeiter!A:A,Mitarbeiter!B:D,"not found",0,1)} -> Alexandre Davids | K37: Vertrieb | L37: Berlin
A38: G0031 | B38: 1004 | C38: 45320 | E38: {=_xlfn.XLOOKUP(A38,Geraete!A:A,Geraete!B:F,"not found",0,1)} -> Laptop | F38: HP EliteBook | G38: 45775 | H38: 1095.62 | I38: München | J38: {=_xlfn.XLOOKUP(GesamtMitDuplikaten!B38,Mitarbeiter!A:A,Mitarbeiter!B:D,"not found",0,1)} -> Klemens Löffler | K38: Vertrieb | L38: Hamburg
A39: G0031 | B39: 1004 | C39: 45336 | E39: {=_xlfn.XLOOKUP(A39,Geraete!A:A,Geraete!B:F,"not found",0,1)} -> Laptop | F39: HP EliteBook | G39: 45775 | H39: 1095.62 | I39: München | J39: {=_xlfn.XLOOKUP(GesamtMitDuplikaten!B39,Mitarbeiter!A:A,Mitarbeiter!B:D,"not found",0,1)} -> Klemens Löffler | K39: Vertrieb | L39: Hamburg
A40: G0032 | B40: 1003 | C40: 45508 | D40: 45871 | E40: {=_xlfn.XLOOKUP(A40,Geraete!A:A,Geraete!B:F,"not found",0,1)} -> Laptop | F40: Lenovo ThinkPad | G40: 44876 | H40: 1801.36 | I40: München | J40: {=_xlfn.XLOOKUP(GesamtMitDuplikaten!B40,Mitarbeiter!A:A,Mitarbeiter!B:D,"not found",0,1)} -> Paul Dobes-Stiffel | K40: Produktion | L40: Hamburg
...

Sheet Gesamt
A1: Gerätenummer | B1: Mitarbeiter-ID | C1: Ausgabe am | D1: Rückgabe am | E1: Gerätetyp | F1: Modell | G1: Kaufdatum | H1: Netto-Kaufpreis | I1: Standort | J1: Mitarbeitername | K1: Abteilung | L1: Standort
A2: G0004 | B2: 1003 | C2: 45827 | D2: 45908 | E2: {=_xlfn.XLOOKUP(Gesamt!$A2,Geraete!A:A,Geraete!B:F,"not found",0,1)} -> Laptop | F2: Dell XPS | G2: 45782 | H2: 1007.88 | I2: München | J2: {=_xlfn.XLOOKUP($B2,Mitarbeiter!A:A,Mitarbeiter!B:D,"not found",0,1)} -> Paul Dobes-Stiffel | K2: Produktion | L2: Hamburg
A3: G0005 | B3: 1009 | C3: 45389 | E3: {=_xlfn.XLOOKUP(Gesamt!$A3,Geraete!A:A,Geraete!B:F,"not found",0,1)} -> Drucker | F3: Canon Pixma | G3: 44503 | H3: 823.23 | I3: Berlin | J3: {=_xlfn.XLOOKUP($B3,Mitarbeiter!A:A,Mitarbeiter!B:D,"not found",0,1)} -> Univ.Prof. Heimo Karge | K3: Marketing | L3: Hamburg
A4: G0006 | B4: 1012 | C4: 45808 | D4: 45818 | E4: {=_xlfn.XLOOKUP(Gesamt!$A4,Geraete!A:A,Geraete!B:F,"not found",0,1)} -> Smartphone | F4: Samsung S21 | G4: 45292 | H4: 1257.96 | I4: München | J4: {=_xlfn.XLOOKUP($B4,Mitarbeiter!A:A,Mitarbeiter!B:D,"not found",0,1)} -> Ariane Klemt-Kaul | K4: IT | L4: München
A5: G0007 | B5: 1001 | C5: 45544 | D5: 45854 | E5: {=_xlfn.XLOOKUP(Gesamt!$A5,Geraete!A:A,Geraete!B:F,"not found",0,1)} -> Laptop | F5: Lenovo ThinkPad | G5: 44360 | H5: 869.09 | I5: Hamburg | J5: {=_xlfn.XLOOKUP($B5,Mitarbeiter!A:A,Mitarbeiter!B:D,"not found",0,1)} -> Aleksandr Weinhage | K5: IT | L5: Berlin
A6: G0009 | B6: 1011 | C6: 45850 | D6: 45853 | E6: {=_xlfn.XLOOKUP(Gesamt!$A6,Geraete!A:A,Geraete!B:F,"not found",0,1)} -> Laptop | F6: Dell XPS | G6: 45026 | H6: 1458.02 | I6: München | J6: {=_xlfn.XLOOKUP($B6,Mitarbeiter!A:A,Mitarbeiter!B:D,"not found",0,1)} -> Auguste Davids | K6: IT | L6: Hamburg
A7: G0011 | B7: 1005 | C7: 45837 | D7: 45898 | E7: {=_xlfn.XLOOKUP(Gesamt!$A7,Geraete!A:A,Geraete!B:F,"not found",0,1)} -> Drucker | F7: Brother HL | G7: 45909 | H7: 1417.1 | I7: München | J7: {=_xlfn.XLOOKUP($B7,Mitarbeiter!A:A,Mitarbeiter!B:D,"not found",0,1)} -> Alexandre Davids | K7: Vertrieb | L7: Berlin
A8: G0013 | B8: 1012 | C8: 45419 | D8: 45470 | E8: {=_xlfn.XLOOKUP(Gesamt!$A8,Geraete!A:A,Geraete!B:F,"not found",0,1)} -> Drucker | F8: Canon Pixma | G8: 44332 | H8: 1898.65 | I8: Hamburg | J8: {=_xlfn.XLOOKUP($B8,Mitarbeiter!A:A,Mitarbeiter!B:D,"not found",0,1)} -> Ariane Klemt-Kaul | K8: IT | L8: München
A9: G0014 | B9: 1001 | C9: 45622 | D9: 45719 | E9: {=_xlfn.XLOOKUP(Gesamt!$A9,Geraete!A:A,Geraete!B:F,"not found",0,1)} -> Laptop | F9: Lenovo ThinkPad | G9: 44258 | H9: 1415.97 | I9: Hamburg | J9: {=_xlfn.XLOOKUP($B9,Mitarbeiter!A:A,Mitarbeiter!B:D,"not found",0,1)} -> Aleksandr Weinhage | K9: IT | L9: Berlin
A10: G0015 | B10: 1010 | C10: 45377 | D10: 45886 | E10: {=_xlfn.XLOOKUP(Gesamt!$A10,Geraete!A:A,Geraete!B:F,"not found",0,1)} -> Smartphone | F10: iPhone 13 | G10: 44824 | H10: 661.44 | I10: München | J10: {=_xlfn.XLOOKUP($B10,Mitarbeiter!A:A,Mitarbeiter!B:D,"not found",0,1)} -> Carolin Hande | K10: IT | L10: Hamburg
A11: G0016 | B11: 1010 | C11: 45866 | E11: {=_xlfn.XLOOKUP(Gesamt!$A11,Geraete!A:A,Geraete!B:F,"not found",0,1)} -> Drucker | F11: Canon Pixma | G11: 45015 | H11: 1501.06 | I11: Berlin | J11: {=_xlfn.XLOOKUP($B11,Mitarbeiter!A:A,Mitarbeiter!B:D,"not found",0,1)} -> Carolin Hande | K11: IT | L11: Hamburg
A12: G0018 | B12: 1011 | C12: 45568 | D12: 45623 | E12: {=_xlfn.XLOOKUP(Gesamt!$A12,Geraete!A:A,Geraete!B:F,"not found",0,1)} -> Tablet | F12: iPad | G12: 44839 | H12: 1688.07 | I12: München | J12: {=_xlfn.XLOOKUP($B12,Mitarbeiter!A:A,Mitarbeiter!B:D,"not found",0,1)} -> Auguste Davids | K12: IT | L12: Hamburg
A13: G0021 | B13: 1008 | C13: 45930 | D13: 45935 | E13: {=_xlfn.XLOOKUP(Gesamt!$A13,Geraete!A:A,Geraete!B:F,"not found",0,1)} -> Monitor | F13: Samsung Curved | G13: 44979 | H13: 1134.16 | I13: München | J13: {=_xlfn.XLOOKUP($B13,Mitarbeiter!A:A,Mitarbeiter!B:D,"not found",0,1)} -> Dipl.-Ing. Klaus-Werner Holsten B.Sc. | K13: IT | L13: Hamburg
A14: G0022 | B14: 1002 | C14: 45899 | D14: 45930 | E14: {=_xlfn.XLOOKUP(Gesamt!$A14,Geraete!A:A,Geraete!B:F,"not found",0,1)} -> Tablet | F14: iPad | G14: 45524 | H14: 1591.98 | I14: Hamburg | J14: {=_xlfn.XLOOKUP($B14,Mitarbeiter!A:A,Mitarbeiter!B:D,"not found",0,1)} -> Eleni Hauffer | K14: IT | L14: Berlin
A15: G0024 | B15: 1005 | C15: 45743 | D15: 45868 | E15: {=_xlfn.XLOOKUP(Gesamt!$A15,Geraete!A:A,Geraete!B:F,"not found",0,1)} -> Monitor | F15: Dell UltraSharp | G15: 44621 | H15: 750.91 | I15: Berlin | J15: {=_xlfn.XLOOKUP($B15,Mitarbeiter!A:A,Mitarbeiter!B:D,"not found",0,1)} -> Alexandre Davids | K15: Vertrieb | L15: Berlin
A16: G0025 | B16: 1005 | C16: 45675 | E16: {=_xlfn.XLOOKUP(Gesamt!$A16,Geraete!A:A,Geraete!B:F,"not found",0,1)} -> Beamer | F16: Epson EB | G16: 45266 | H16: 545.46 | I16: Berlin | J16: {=_xlfn.XLOOKUP($B16,Mitarbeiter!A:A,Mitarbeiter!B:D,"not found",0,1)} -> Alexandre Davids | K16: Vertrieb | L16: Berlin
A17: G0027 | B17: 1004 | C17: 45403 | D17: 45839 | E17: {=_xlfn.XLOOKUP(Gesamt!$A17,Geraete!A:A,Geraete!B:F,"not found",0,1)} -> Monitor | F17: Samsung Curved | G17: 44766 | H17: 501.64 | I17: München | J17: {=_xlfn.XLOOKUP($B17,Mitarbeiter!A:A,Mitarbeiter!B:D,"not found",0,1)} -> Klemens Löffler | K17: Vertrieb | L17: Hamburg
A18: G0028 | B18: 1004 | C18: 45523 | E18: {=_xlfn.XLOOKUP(Gesamt!$A18,Geraete!A:A,Geraete!B:F,"not found",0,1)} -> Beamer | F18: Epson EB | G18: 44945 | H18: 1246.58 | I18: Hamburg | J18: {=_xlfn.XLOOKUP($B18,Mitarbeiter!A:A,Mitarbeiter!B:D,"not found",0,1)} -> Klemens Löffler | K18: Vertrieb | L18: Hamburg
A19: G0029 | B19: 1002 | C19: 45921 | D19: 45934 | E19: {=_xlfn.XLOOKUP(Gesamt!$A19,Geraete!A:A,Geraete!B:F,"not found",0,1)} -> Laptop | F19: Lenovo ThinkPad | G19: 44337 | H19: 1553.15 | I19: Hamburg | J19: {=_xlfn.XLOOKUP($B19,Mitarbeiter!A:A,Mitarbeiter!B:D,"not found",0,1)} -> Eleni Hauffer | K19: IT | L19: Berlin
A20: G0030 | B20: 1012 | C20: 45792 | D20: 45905 | E20: {=_xlfn.XLOOKUP(Gesamt!$A20,Geraete!A:A,Geraete!B:F,"not found",0,1)} -> Beamer | F20: Epson EB | G20: 44647 | H20: 1629.76 | I20: München | J20: {=_xlfn.XLOOKUP($B20,Mitarbeiter!A:A,Mitarbeiter!B:D,"not found",0,1)} -> Ariane Klemt-Kaul | K20: IT | L20: München
A21: G0031 | B21: 1004 | C21: 45320 | E21: {=_xlfn.XLOOKUP(Gesamt!$A21,Geraete!A:A,Geraete!B:F,"not found",0,1)} -> Laptop | F21: HP EliteBook | G21: 45775 | H21: 1095.62 | I21: München | J21: {=_xlfn.XLOOKUP($B21,Mitarbeiter!A:A,Mitarbeiter!B:D,"not found",0,1)} -> Klemens Löffler | K21: Vertrieb | L21: Hamburg
A22: G0032 | B22: 1003 | C22: 45508 | D22: 45871 | E22: {=_xlfn.XLOOKUP(Gesamt!$A22,Geraete!A:A,Geraete!B:F,"not found",0,1)} -> Laptop | F22: Lenovo ThinkPad | G22: 44876 | H22: 1801.36 | I22: München | J22: {=_xlfn.XLOOKUP($B22,Mitarbeiter!A:A,Mitarbeiter!B:D,"not found",0,1)} -> Paul Dobes-Stiffel | K22: Produktion | L22: Hamburg
A23: G0033 | B23: 1009 | C23: 45740 | D23: 45784 | E23: {=_xlfn.XLOOKUP(Gesamt!$A23,Geraete!A:A,Geraete!B:F,"not found",0,1)} -> Beamer | F23: BenQ MW550 | G23: 44623 | H23: 1212.29 | I23: Berlin | J23: {=_xlfn.XLOOKUP($B23,Mitarbeiter!A:A,Mitarbeiter!B:D,"not found",0,1)} -> Univ.Prof. Heimo Karge | K23: Marketing | L23: Hamburg
A24: G0035 | B24: 1009 | C24: 45421 | E24: {=_xlfn.XLOOKUP(Gesamt!$A24,Geraete!A:A,Geraete!B:F,"not found",0,1)} -> Beamer | F24: BenQ MW550 | G24: 45294 | H24: 644.54 | I24: Berlin | J24: {=_xlfn.XLOOKUP($B24,Mitarbeiter!A:A,Mitarbeiter!B:D,"not found",0,1)} -> Univ.Prof. Heimo Karge | K24: Marketing | L24: Hamburg

Sheet Aufgabe D1
A1: Rückgabe am | B1: (Multiple Items)
A3: Row Labels | B3: Sum of Netto-Kaufpreis
A4: G0004 | B4: 2015.76
A5: G0005 | B5: 1646.46
A6: G0006 | B6: 1257.96
A7: G0007 | B7: 869.09
A8: G0009 | B8: 1458.02
A9: G0011 | B9: 1417.1
A10: G0013 | B10: 3797.3
A11: G0014 | B11: 1415.97
A12: G0015 | B12: 661.44
A13: G0016 | B13: 6004.24
A14: G0018 | B14: 1688.07
A15: G0021 | B15: 1134.16
... A24: Grand Total | B24: 38121.56

Sheet Aufgabe D2
A1: Gerätenummer | B1: Mitarbeiter-ID | C1: Ausgabe am | D1: Rückgabe am | E1: Gerätetyp | F1: Modell | G1: Kaufdatum | H1: Netto-Kaufpreis | I1: Standort | J1: Mitarbeitername | K1: Abteilung | L1: Standort
A2: G0004 | B2: 1003 | C2: 45827 | D2: 45908 | E2: {=_xlfn.XLOOKUP(Gesamt!$A2,Geraete!A:A,Geraete!B:F,"not found",0,1)} -> Laptop | F2: Dell XPS | G2: 45782 | H2: 1007.88 | I2: München | J2: {=_xlfn.XLOOKUP($B2,Mitarbeiter!A:A,Mitarbeiter!B:D,"not found",0,1)} -> Paul Dobes-Stiffel | K2: Produktion | L2: Hamburg
A3: G0005 | B3: 1009 | C3: 45389 | E3: {=_xlfn.XLOOKUP(Gesamt!$A3,Geraete!A:A,Geraete!B:F,"not found",0,1)} -> Drucker | F3: Canon Pixma | G3: 44503 | H3: 823.23 | I3: Berlin | J3: {=_xlfn.XLOOKUP($B3,Mitarbeiter!A:A,Mitarbeiter!B:D,"not found",0,1)} -> Univ.Prof. Heimo Karge | K3: Marketing | L3: Hamburg
A4: G0006 | B4: 1012 | C4: 45808 | D4: 45818 | E4: {=_xlfn.XLOOKUP(Gesamt!$A4,Geraete!A:A,Geraete!B:F,"not found",0,1)} -> Smartphone | F4: Samsung S21 | G4: 45292 | H4: 1257.96 | I4: München | J4: {=_xlfn.XLOOKUP($B4,Mitarbeiter!A:A,Mitarbeiter!B:D,"not found",0,1)} -> Ariane Klemt-Kaul | K4: IT | L4: München
A5: G0007 | B5: 1001 | C5: 45544 | D5: 45854 | E5: {=_xlfn.XLOOKUP(Gesamt!$A5,Geraete!A:A,Geraete!B:F,"not found",0,1)} -> Laptop | F5: Lenovo ThinkPad | G5: 44360 | H5: 869.09 | I5: Hamburg | J5: {=_xlfn.XLOOKUP($B5,Mitarbeiter!A:A,Mitarbeiter!B:D,"not found",0,1)} -> Aleksandr Weinhage | K5: IT | L5: Berlin
A6: G0009 | B6: 1011 | C6: 45850 | D6: 45853 | E6: {=_xlfn.XLOOKUP(Gesamt!$A6,Geraete!A:A,Geraete!B:F,"not found",0,1)} -> Laptop | F6: Dell XPS | G6: 45026 | H6: 1458.02 | I6: München | J6: {=_xlfn.XLOOKUP($B6,Mitarbeiter!A:A,Mitarbeiter!B:D,"not found",0,1)} -> Auguste Davids | K6: IT | L6: Hamburg
A7: G0011 | B7: 1005 | C7: 45837 | D7: 45898 | E7: {=_xlfn.XLOOKUP(Gesamt!$A7,Geraete!A:A,Geraete!B:F,"not found",0,1)} -> Drucker | F7: Brother HL | G7: 45909 | H7: 1417.1 | I7: München | J7: {=_xlfn.XLOOKUP($B7,Mitarbeiter!A:A,Mitarbeiter!B:D,"not found",0,1)} -> Alexandre Davids | K7: Vertrieb | L7: Berlin
A8: G0013 | B8: 1012 | C8: 45419 | D8: 45470 | E8: {=_xlfn.XLOOKUP(Gesamt!$A8,Geraete!A:A,Geraete!B:F,"not found",0,1)} -> Drucker | F8: Canon Pixma | G8: 44332 | H8: 1898.65 | I8: Hamburg | J8: {=_xlfn.XLOOKUP($B8,Mitarbeiter!A:A,Mitarbeiter!B:D,"not found",0,1)} -> Ariane Klemt-Kaul | K8: IT | L8: München
A9: G0014 | B9: 1001 | C9: 45622 | D9: 45719 | E9: {=_xlfn.XLOOKUP(Gesamt!$A9,Geraete!A:A,Geraete!B:F,"not found",0,1)} -> Laptop | F9: Lenovo ThinkPad | G9: 44258 | H9: 1415.97 | I9: Hamburg | J9: {=_xlfn.XLOOKUP($B9,Mitarbeiter!A:A,Mitarbeiter!B:D,"not found",0,1)} -> Aleksandr Weinhage | K9: IT | L9: Berlin
A10: G0015 | B10: 1010 | C10: 45377 | D10: 45886 | E10: {=_xlfn.XLOOKUP(Gesamt!$A10,Geraete!A:A,Geraete!B:F,"not found",0,1)} -> Smartphone | F10: iPhone 13 | G10: 44824 | H10: 661.44 | I10: München | J10: {=_xlfn.XLOOKUP($B10,Mitarbeiter!A:A,Mitarbeiter!B:D,"not found",0,1)} -> Carolin Hande | K10: IT | L10: Hamburg
A11: G0016 | B11: 1010 | C11: 45866 | E11: {=_xlfn.XLOOKUP(Gesamt!$A11,Geraete!A:A,Geraete!B:F,"not found",0,1)} -> Drucker | F11: Canon Pixma | G11: 45015 | H11: 1501.06 | I11: Berlin | J11: {=_xlfn.XLOOKUP($B11,Mitarbeiter!A:A,Mitarbeiter!B:D,"not found",0,1)} -> Carolin Hande | K11: IT | L11: Hamburg
A12: G0018 | B12: 1011 | C12: 45568 | D12: 45623 | E12: {=_xlfn.XLOOKUP(Gesamt!$A12,Geraete!A:A,Geraete!B:F,"not found",0,1)} -> Tablet | F12: iPad | G12: 44839 | H12: 1688.07 | I12: München | J12: {=_xlfn.XLOOKUP($B12,Mitarbeiter!A:A,Mitarbeiter!B:D,"not found",0,1)} -> Auguste Davids | K12: IT | L12: Hamburg
A13: G0021 | B13: 1008 | C13: 45930 | D13: 45935 | E13: {=_xlfn.XLOOKUP(Gesamt!$A13,Geraete!A:A,Geraete!B:F,"not found",0,1)} -> Monitor | F13: Samsung Curved | G13: 44979 | H13: 1134.16 | I13: München | J13: {=_xlfn.XLOOKUP($B13,Mitarbeiter!A:A,Mitarbeiter!B:D,"not found",0,1)} -> Dipl.-Ing. Klaus-Werner Holsten B.Sc. | K13: IT | L13: Hamburg
A14: G0022 | B14: 1002 | C14: 45899 | D14: 45930 | E14: {=_xlfn.XLOOKUP(Gesamt!$A14,Geraete!A:A,Geraete!B:F,"not found",0,1)} -> Tablet | F14: iPad | G14: 45524 | H14: 1591.98 | I14: Hamburg | J14: {=_xlfn.XLOOKUP($B14,Mitarbeiter!A:A,Mitarbeiter!B:D,"not found",0,1)} -> Eleni Hauffer | K14: IT | L14: Berlin
A15: G0024 | B15: 1005 | C15: 45743 | D15: 45868 | E15: {=_xlfn.XLOOKUP(Gesamt!$A15,Geraete!A:A,Geraete!B:F,"not found",0,1)} -> Monitor | F15: Dell UltraSharp | G15: 44621 | H15: 750.91 | I15: Berlin | J15: {=_xlfn.XLOOKUP($B15,Mitarbeiter!A:A,Mitarbeiter!B:D,"not found",0,1)} -> Alexandre Davids | K15: Vertrieb | L15: Berlin
A16: G0025 | B16: 1005 | C16: 45675 | E16: {=_xlfn.XLOOKUP(Gesamt!$A16,Geraete!A:A,Geraete!B:F,"not found",0,1)} -> Beamer | F16: Epson EB | G16: 45266 | H16: 545.46 | I16: Berlin | J16: {=_xlfn.XLOOKUP($B16,Mitarbeiter!A:A,Mitarbeiter!B:D,"not found",0,1)} -> Alexandre Davids | K16: Vertrieb | L16: Berlin
A17: G0027 | B17: 1004 | C17: 45403 | D17: 45839 | E17: {=_xlfn.XLOOKUP(Gesamt!$A17,Geraete!A:A,Geraete!B:F,"not found",0,1)} -> Monitor | F17: Samsung Curved | G17: 44766 | H17: 501.64 | I17: München | J17: {=_xlfn.XLOOKUP($B17,Mitarbeiter!A:A,Mitarbeiter!B:D,"not found",0,1)} -> Klemens Löffler | K17: Vertrieb | L17: Hamburg
A18: G0028 | B18: 1004 | C18: 45523 | E18: {=_xlfn.XLOOKUP(Gesamt!$A18,Geraete!A:A,Geraete!B:F,"not found",0,1)} -> Beamer | F18: Epson EB | G18: 44945 | H18: 1246.58 | I18: Hamburg | J18: {=_xlfn.XLOOKUP($B18,Mitarbeiter!A:A,Mitarbeiter!B:D,"not found",0,1)} -> Klemens Löffler | K18: Vertrieb | L18: Hamburg
A19: G0029 | B19: 1002 | C19: 45921 | D19: 45934 | E19: {=_xlfn.XLOOKUP(Gesamt!$A19,Geraete!A:A,Geraete!B:F,"not found",0,1)} -> Laptop | F19: Lenovo ThinkPad | G19: 44337 | H19: 1553.15 | I19: Hamburg | J19: {=_xlfn.XLOOKUP($B19,Mitarbeiter!A:A,Mitarbeiter!B:D,"not found",0,1)} -> Eleni Hauffer | K19: IT | L19: Berlin
A20: G0030 | B20: 1012 | C20: 45792 | D20: 45905 | E20: {=_xlfn.XLOOKUP(Gesamt!$A20,Geraete!A:A,Geraete!B:F,"not found",0,1)} -> Beamer | F20: Epson EB | G20: 44647 | H20: 1629.76 | I20: München | J20: {=_xlfn.XLOOKUP($B20,Mitarbeiter!A:A,Mitarbeiter!B:D,"not found",0,1)} -> Ariane Klemt-Kaul | K20: IT | L20: München
A21: G0031 | B21: 1004 | C21: 45320 | E21: {=_xlfn.XLOOKUP(Gesamt!$A21,Geraete!A:A,Geraete!B:F,"not found",0,1)} -> Laptop | F21: HP EliteBook | G21: 45775 | H21: 1095.62 | I21: München | J21: {=_xlfn.XLOOKUP($B21,Mitarbeiter!A:A,Mitarbeiter!B:D,"not found",0,1)} -> Klemens Löffler | K21: Vertrieb | L21: Hamburg
A22: G0032 | B22: 1003 | C22: 45508 | D22: 45871 | E22: {=_xlfn.XLOOKUP(Gesamt!$A22,Geraete!A:A,Geraete!B:F,"not found",0,1)} -> Laptop | F22: Lenovo ThinkPad | G22: 44876 | H22: 1801.36 | I22: München | J22: {=_xlfn.XLOOKUP($B22,Mitarbeiter!A:A,Mitarbeiter!B:D,"not found",0,1)} -> Paul Dobes-Stiffel | K22: Produktion | L22: Hamburg
A23: G0033 | B23: 1009 | C23: 45740 | D23: 45784 | E23: {=_xlfn.XLOOKUP(Gesamt!$A23,Geraete!A:A,Geraete!B:F,"not found",0,1)} -> Beamer | F23: BenQ MW550 | G23: 44623 | H23: 1212.29 | I23: Berlin | J23: {=_xlfn.XLOOKUP($B23,Mitarbeiter!A:A,Mitarbeiter!B:D,"not found",0,1)} -> Univ.Prof. Heimo Karge | K23: Marketing | L23: Hamburg
A24: G0035 | B24: 1009 | C24: 45421 | E24: {=_xlfn.XLOOKUP(Gesamt!$A24,Geraete!A:A,Geraete!B:F,"not found",0,1)} -> Beamer | F24: BenQ MW550 | G24: 45294 | H24: 644.54 | I24: Berlin | J24: {=_xlfn.XLOOKUP($B24,Mitarbeiter!A:A,Mitarbeiter!B:D,"not found",0,1)} -> Univ.Prof. Heimo Karge | K24: Marketing | L24: Hamburg

Sheet Aufgabe D3+4
A3: Anzahl Ausleihen | B3: Column Labels
A4: Gerätetyp | B4: Berlin | C4: Hamburg | D4: München | E4: Grand Total
A5: Beamer | B5: 7 | C5: 3 | D5: 2 | E5: 12
A6: Drucker | B6: 9 | C6: 2 | D6: 1 | E6: 12
A7: Laptop | C7: 4 | D7: 6 | E7: 10
A8: Monitor | B8: 2 | D8: 2 | E8: 4
A9: Smartphone | D9: 4 | E9: 4
A10: Tablet | C10: 2 | D10: 1 | E10: 3
A11: Grand Total | B11: 18 | C11: 11 | D11: 16 | E11: 45
